<?xml version='1.0'?>
<sdf version='1.6'>
  <model name='fusionbot'>
    <link name='base_footprint'>
      <pose frame=''>0 0 0 0 -0 0</pose>
      <inertial>
        <pose frame=''>0.003759 0 0.052804 0 -0 0</pose>
        <mass>2.30796</mass>
        <inertia>
          <ixx>0.00789</ixx>
          <ixy>0</ixy>
          <ixz>-0.000325</ixz>
          <iyy>0.008347</iyy>
          <iyz>0</iyz>
          <izz>0.01475</izz>
        </inertia>
      </inertial>
      <collision name='base_footprint_fixed_joint_lump__base_link_collision'>
        <pose frame=''>0 0 0 0 -0 0</pose>
        <geometry>
          <mesh>
            <scale>0.001 0.001 0.001</scale>
            <uri>model://fusionbot/meshes/fusionbot/base_link.stl</uri>
          </mesh>
        </geometry>
        <surface>
          <contact>
            <ode/>
          </contact>
          <friction>
            <ode>
              <mu>0.1</mu>
              <mu2>0.1</mu2>
            </ode>
          </friction>
        </surface>
      </collision>
      <visual name='base_footprint_fixed_joint_lump__base_link_visual'>
        <pose frame=''>0 0 0 0 -0 0</pose>
        <geometry>
          <mesh>
            <scale>0.001 0.001 0.001</scale>
            <uri>model://fusionbot/meshes/fusionbot/base_link.stl</uri>
          </mesh>
        </geometry>
        <material>
          <script>
            <name>Gazebo/Silver</name>
            <uri>file://media/materials/scripts/gazebo.material</uri>
          </script>
        </material>
      </visual>
      <gravity>1</gravity>
      <velocity_decay/>
      <self_collide>1</self_collide>
      <gravity>1</gravity>
    </link>
    <link name='left_wheel_1'>
      <pose frame=''>0 0.1 0.05 0 -0 0</pose>
      <inertial>
        <pose frame=''>-0 0.0125 0 0 -0 0</pose>
        <mass>0.182605</mass>
        <inertia>
          <ixx>0.000124</ixx>
          <ixy>0</ixy>
          <ixz>0</ixz>
          <iyy>0.000228</iyy>
          <iyz>-0</iyz>
          <izz>0.000124</izz>
        </inertia>
      </inertial>
      <collision name='left_wheel_1_collision'>
        <pose frame=''>-0 -0.1 -0.05 0 -0 0</pose>
        <geometry>
          <mesh>
            <scale>0.001 0.001 0.001</scale>
            <uri>model://fusionbot/meshes/fusionbot/left_wheel_1.stl</uri>
          </mesh>
        </geometry>
        <surface>
          <contact>
            <ode/>
          </contact>
          <friction>
            <ode>
              <mu>1500</mu>
              <mu2>1500</mu2>
            </ode>
          </friction>
        </surface>
      </collision>
      <visual name='left_wheel_1_visual'>
        <pose frame=''>-0 -0.1 -0.05 0 -0 0</pose>
        <geometry>
          <mesh>
            <scale>0.001 0.001 0.001</scale>
            <uri>model://fusionbot/meshes/fusionbot/left_wheel_1.stl</uri>
          </mesh>
        </geometry>
        <material>
          <script>
            <name>Gazebo/Silver</name>
            <uri>file://media/materials/scripts/gazebo.material</uri>
          </script>
        </material>
      </visual>
      <gravity>1</gravity>
      <velocity_decay/>
      <self_collide>1</self_collide>
    </link>
    <joint name='left_wheel_joint' type='revolute'>
      <child>left_wheel_1</child>
      <parent>base_footprint</parent>
      <axis>
        <xyz>0 1 0</xyz>
        <limit>
          <lower>-1e+16</lower>
          <upper>1e+16</upper>
        </limit>
        <dynamics>
          <spring_reference>0</spring_reference>
          <spring_stiffness>0</spring_stiffness>
        </dynamics>
        <use_parent_model_frame>0</use_parent_model_frame>
      </axis>
    </joint>
    <link name='lidar_1'>
      <pose frame=''>0.05 0 0.11 0 -0 0</pose>
      <inertial>
        <pose frame=''>0 0 0.0125 0 -0 0</pose>
        <mass>0.755259</mass>
        <inertia>
          <ixx>0.000271</ixx>
          <ixy>0</ixy>
          <ixz>0</ixz>
          <iyy>0.000271</iyy>
          <iyz>-0</iyz>
          <izz>0.000463</izz>
        </inertia>
      </inertial>
      <collision name='lidar_1_collision'>
        <pose frame=''>-0.05 -0 -0.11 0 -0 0</pose>
        <geometry>
          <mesh>
            <scale>0.001 0.001 0.001</scale>
            <uri>model://fusionbot/meshes/fusionbot/lidar_1.stl</uri>
          </mesh>
        </geometry>
        <surface>
          <contact>
            <ode/>
          </contact>
          <friction>
            <ode>
              <mu>0.2</mu>
              <mu2>0.2</mu2>
            </ode>
          </friction>
        </surface>
      </collision>
      <visual name='lidar_1_visual'>
        <pose frame=''>-0.05 -0 -0.11 0 -0 0</pose>
        <geometry>
          <mesh>
            <scale>0.001 0.001 0.001</scale>
            <uri>model://fusionbot/meshes/fusionbot/lidar_1.stl</uri>
          </mesh>
        </geometry>
        <material>
          <script>
            <name>Gazebo/Silver</name>
            <uri>file://media/materials/scripts/gazebo.material</uri>
          </script>
        </material>
      </visual>
      <gravity>1</gravity>
      <velocity_decay/>
      <self_collide>1</self_collide>
      <sensor name="rp_lidar_a1" type="ray">
        <always_on>true</always_on>
        <visualize>true</visualize>
        <pose>0.0 0 0.02 0 0 0</pose>
        <update_rate>5.5</update_rate>
        <ray>
          <scan>
            <horizontal>
              <samples>360</samples>
              <resolution>1.000000</resolution>
              <!-- <min_angle>-3.14</min_angle> -->
              <!-- <max_angle>3.14</max_angle> -->
              <min_angle>-1.5707</min_angle>
              <max_angle>1.5707</max_angle>
            </horizontal>
          </scan>
          <range>
            <min>0.2</min>
            <max>10.0</max>
            <resolution>0.05</resolution>
          </range>
          <noise>
            <type>gaussian</type>
            <mean>0.0</mean>
            <stddev>0.01</stddev>
          </noise>
        </ray>
        <plugin name="fusionbot_laserscan" filename="libgazebo_ros_ray_sensor.so">
          <ros>
            <remapping>~/out:=scan</remapping>
          </ros>
          <output_type>sensor_msgs/LaserScan</output_type>
          <frame_name>laser_frame</frame_name>
        </plugin>
      </sensor>
    </link>
    <joint name='lidar_joint' type='fixed'>
      <child>lidar_1</child>
      <parent>base_footprint</parent>
      <pose frame=''>0 0 0 0 -0 0</pose>
      <physics>
        <ode>
          <limit>
            <cfm>0</cfm>
            <erp>0.2</erp>
          </limit>
          <suspension>
            <cfm>0</cfm>
            <erp>0.2</erp>
          </suspension>
        </ode>
      </physics>
    </joint>

    <link name='right_wheel_1'>
      <pose frame=''>0 -0.1 0.05 0 -0 0</pose>
      <inertial>
        <pose frame=''>-0 -0.0125 0 0 -0 0</pose>
        <mass>0.182605</mass>
        <inertia>
          <ixx>0.000124</ixx>
          <ixy>-0</ixy>
          <ixz>0</ixz>
          <iyy>0.000228</iyy>
          <iyz>0</iyz>
          <izz>0.000124</izz>
        </inertia>
      </inertial>
      <collision name='right_wheel_1_collision'>
        <pose frame=''>-0 0.1 -0.05 0 -0 0</pose>
        <geometry>
          <mesh>
            <scale>0.001 0.001 0.001</scale>
            <uri>model://fusionbot/meshes/fusionbot/right_wheel_1.stl</uri>
          </mesh>
        </geometry>
        <surface>
          <contact>
            <ode/>
          </contact>
          <friction>
            <ode>
              <mu>1500</mu>
              <mu2>1500</mu2>
            </ode>
          </friction>
        </surface>
      </collision>
      <visual name='right_wheel_1_visual'>
        <pose frame=''>-0 0.1 -0.05 0 -0 0</pose>
        <geometry>
          <mesh>
            <scale>0.001 0.001 0.001</scale>
            <uri>model://fusionbot/meshes/fusionbot/right_wheel_1.stl</uri>
          </mesh>
        </geometry>
        <material>
          <script>
            <name>Gazebo/Silver</name>
            <uri>file://media/materials/scripts/gazebo.material</uri>
          </script>
        </material>
      </visual>
      <gravity>1</gravity>
      <velocity_decay/>
      <self_collide>1</self_collide>
    </link>
    <joint name='right_wheel_joint' type='revolute'>
      <child>right_wheel_1</child>
      <parent>base_footprint</parent>
      <axis>
        <xyz>0 1 0</xyz>
        <limit>
          <lower>-1e+16</lower>
          <upper>1e+16</upper>
        </limit>
        <dynamics>
          <spring_reference>0</spring_reference>
          <spring_stiffness>0</spring_stiffness>
        </dynamics>
        <use_parent_model_frame>0</use_parent_model_frame>
      </axis>
    </joint>
    <static>0</static>
    <plugin name='control' filename='libgazebo_ros_control.so'/>

    <plugin name='differential_drive_controller' filename='libgazebo_ros_diff_drive.so'>
      <update_rate>30</update_rate>
      <left_joint>left_wheel_joint</left_joint>
      <right_joint>right_wheel_joint</right_joint>
      <wheel_separation>0.2</wheel_separation>
      <wheel_diameter>0.1</wheel_diameter>
      <max_wheel_torque>50</max_wheel_torque>
      <max_wheel_acceleration>1.0</max_wheel_acceleration>
      <command_topic>cmd_vel</command_topic>
      <publish_odom>1</publish_odom>
      <publish_odom_tf>1</publish_odom_tf>
      <publish_wheel_tf>0</publish_wheel_tf>
      <odometry_topic>odom</odometry_topic>
      <odometry_frame>odom</odometry_frame>
      <robot_base_frame>base_footprint</robot_base_frame>
    </plugin>

    <plugin name='fusionbot_joint_state' filename='libgazebo_ros_joint_state_publisher.so'>
      <ros>
        <remapping>~/out:=joint_states</remapping>
      </ros>
      <update_rate>30</update_rate>
      <joint_name>right_wheel_joint</joint_name>
      <joint_name>left_wheel_joint</joint_name>
    </plugin>
  </model>
</sdf>
